#!/usr/bin/env python
# -*- coding: utf-8 -*-
#
# Copyright (C) 2009 Pierre-Andr√© Saulais <pasaulais@free.fr>
#
# This file is part of the Spark File-transfer Tool.
#
# Spark is free software; you can redistribute it and/or modify
# it under the terms of the GNU General Public License as published by
# the Free Software Foundation; either version 2 of the License, or
# (at your option) any later version.
#
# Spark is distributed in the hope that it will be useful,
# but WITHOUT ANY WARRANTY; without even the implied warranty of
# MERCHANTABILITY or FITNESS FOR A PARTICULAR PURPOSE.  See the
# GNU General Public License for more details.
#
# You should have received a copy of the GNU General Public License
# along with Spark; if not, write to the Free Software
# Foundation, Inc., 51 Franklin St, Fifth Floor, Boston, MA  02110-1301  USA

import unittest
import threading
from spark.async import *
from spark.messaging import *
from spark.tests.common import run_tests, processTimeout, assertMatch, assertNoMatch

class FutureTest(unittest.TestCase):
    def testCompleted(self):
        f = Future()
        self.assertTrue(f.pending)
        f.completed(("spam", "eggs"))
        self.assertFalse(f.pending)
        self.assertEqual(("spam", "eggs"), f.result)
    
    def testFailedSimple(self):
        f = Future()
        self.assertTrue(f.pending)
        f.failed()
        self.assertFalse(f.pending)
        try:
            r = f.result
            self.fail("result didn't raise an exception")
        except:
            pass
    
    def testFailedException(self):
        f = Future()
        try:
            raise KeyError("The key was not found")
        except:
            f.failed()

        try:
            r = f.result
            self.fail("result didn't raise an exception")
        except TaskError:
            pass
    
    def testCompletedTwice(self):
        """ completed() should raise an exception the second time """
        f = Future()
        f.completed(("spam", "eggs"))
        self.assertRaises(Exception, f.completed, ("eggs", "spam"))
    
    def testCompletedAfterFailed(self):
        """ completed() should raise an exception after failed() is called """
        f = Future()
        f.failed()
        self.assertRaises(Exception, f.completed, "eggs", "spam")
    
    def testFailedTwice(self):
        """ failed() should raise an exception the second time """
        f = Future()
        f.failed()
        self.assertRaises(Exception, f.failed)
    
    def testFailedAfterCompleted(self):
        """ failedd() should raise an exception after completed() is called """
        f = Future()
        f.completed(("eggs", "spam"))
        self.assertRaises(Exception, f.failed)
    
    def testCallback(self):
        """ The callback should be invoked with the right arguments (result plus positional args). """
        result = []
        def bar(prev, *args):
            result.append(prev.result + args)
        f = Future()
        f.after(bar, 1, 2, 3)
        f.completed(("spam", "eggs"))
        self.assertEqual(1, len(result))
        self.assertEqual(("spam", "eggs", 1, 2, 3), result[0])
    
    def testAfterCompleted(self):
        """ The callback should be invoked even when after() is called after completion. """
        result = []
        def bar(prev, *args):
            result.append(prev.result + args)
        f = Future()
        f.completed(("spam", "eggs"))
        f.after(bar, 1, 2, 3)
        self.assertEqual(1, len(result))
        self.assertEqual(("spam", "eggs", 1, 2, 3), result[0])
    
    def testBoundMethodCallback(self):
        """ Callbacks to bound methods should be usable as continuations. """
        class Foo(object):
            def __init__(self):
                self.result = []
            def bar(self, f):
                self.result.append(f.result)
        foo = Foo()
        f = Future()
        f.after(foo.bar)
        f.completed(("spam", "eggs"))
        self.assertEqual(1, len(foo.result))
        self.assertEqual(("spam", "eggs"), foo.result[0])
    
    def testRunCoroutine(self):
        readers = []
        writers = []
        results = []
        def beginRead():
            cont = Future()
            readers.append(cont)
            return cont
        
        def beginWrite(s):
            cont = Future()
            writers.append((cont, s))
            return cont
        
        def coroutine():
            val = yield beginRead()
            results.append(val)
            yield beginWrite("bar")
            yield "baz"
        
        def success(cont):
            results.append(cont.result)
        
        f = Future()
        f.after(success)
        f.run_coroutine(coroutine())
        
        # the coroutine should be waiting for beginRead to finish
        self.assertEqual(1, len(readers))
        self.assertEqual(0, len(writers))
        readers.pop().completed("foo")
        self.assertEqual(1, len(results))
        self.assertEqual("foo", results[0])
        
        # the coroutine should be waiting for beginWrite to finish
        self.assertEqual(0, len(readers))
        self.assertEqual(1, len(writers))
        cont, val = writers.pop()
        self.assertEqual("bar", val)
        cont.completed()
        
        # the coroutine should have completed
        self.assertEqual(0, len(readers))
        self.assertEqual(0, len(writers))
        self.assertEqual(2, len(results))
        self.assertEqual("baz", results[1])
    
    def testRunCoroutineHandledException(self):
        """ Exceptions raised by futures should look like as if they had been raised by 'yield'. """
        callers = []
        results = []
        def buggyFunc():
            cont = Future()
            callers.append(cont)
            return cont
        
        def coroutine():
            try:
                val = yield buggyFunc()
            except Exception as e:
                results.append(e)
        
        f = Future()
        f.run_coroutine(coroutine())
        callers.pop().failed(ZeroDivisionError())
        self.assertEqual(1, len(results))
    
    def testRunCoroutineUnhandledException(self):
        """ Unhandled exceptions raised in coroutines should fail the future's task. """
        callers = []
        results = []
        def buggyFunc():
            cont = Future()
            callers.append(cont)
            return cont
        
        def coroutine():
            val = yield buggyFunc()
        
        f = Future()
        f.run_coroutine(coroutine())
        callers.pop().failed(ZeroDivisionError())
        try:
            f.wait()
        except:
            pass
        else:
            self.fail("wait() should have raised an exception")

class ProcessTest(unittest.TestCase):
    @processTimeout(1.0)
    def testSpawn(self):
        """ Process.spawn should invoke the callable """
        f = Future()
        def entry():
            f.completed("foo")
        Process.spawn(entry)
        self.assertEqual("foo", f.result)
    
    @processTimeout(1.0)
    def testSendReceiveMessage(self):
        """ Messages sent to a PID using Process.send should be received when calling Process.receive """
        pid = Process.current()
        def entry():
            Process.send(pid, Process.receive() + "bar")
        p = Process.spawn(entry)
        Process.send(p, "foo")
        self.assertEqual("foobar", Process.receive())
    
    @processTimeout(1.0)
    def testSendReceiveOrder(self):
        """ Messages should be received in the order they are sent """
        pid = Process.current()
        def entry():
            messages = []
            while True:
                m = Process.receive()
                if m is None:
                    break
                messages.append(m)
            Process.send(pid, messages)
        p = Process.spawn(entry)
        Process.send(p, "foo")
        Process.send(p, "bar")
        Process.send(p, "baz")
        Process.send(p, None)
        self.assertEqual(["foo", "bar", "baz"], Process.receive())
    
    def testAttach(self):
        """ Threads that have been attached should be able to receive messages """
        cont = Future()
        def entry():
            pid = Process.attach()
            try:
                Process.spawn(Process.send, (pid, "foo"))
                cont.completed(Process.receive())
            finally:
                Process.detach()
        t = threading.Thread(target=entry)
        t.daemon = True
        t.start()
        self.assertEqual("foo", cont.wait(1.0))

class EventSenderTest(unittest.TestCase):
    @processTimeout(1.0)
    def testSendEvent(self):
        """ EventSender should send messages that match its pattern"""
        ev = EventSender("foo")
        ev2 = EventSender("bar", int)
        ev.suscribe()
        ev2.suscribe()
        ev()
        ev2(1)
        assertMatch(Event("foo"), ev.pattern)
        assertMatch(Event("bar", int), ev2.pattern)
        assertMatch(Event("foo"), Process.receive())
        assertMatch(Event("bar", int), Process.receive())
    
    @processTimeout(1.0)
    def testPatternMismatch(self):
        """ EventSender should not send messages that don't match its pattern"""
        ev = EventSender("foo")
        ev2 = EventSender("bar", int)
        ev.suscribe()
        ev2.suscribe()
        events = [(ev, ["bar"]), (ev2, ["baz"])]
        for sender, args in events:
            try:
                sender(*args)
            except Exception:
                pass
            else:
                event = Event(sender.name, *args)
                self.fail("Sent %s which doesn't match the pattern %s"
                    % (repr(event), repr(sender.pattern)))

class ProcessMessageTest(unittest.TestCase):
    def testMessageAsSequence(self):
        c = Command('bind', '127.0.0.1:4550')
        self.assertEqual(2, len(c))
        self.assertEqual('bind', c[0])
        self.assertEqual('127.0.0.1:4550', c[1])
        self.assertEqual(['bind', '127.0.0.1:4550'], list(c))
        self.assertEqual(('127.0.0.1:4550', ), c[1:])

if __name__ == '__main__':
    run_tests()